Workbook

Sheet ASOSIY REYTING & BALANS
A1: HAYDOVCHILAR REYSLARI, OYLIKLARI VA KASSA BALANSI
A2: Kunlik jadvalga 'pustoy' deb yozsangiz, asosiy jadvalda avtomat hisoblab oylikdan chegiradi.
A4: T/r | B4: Haydovchi F.I.O | C4: Davlat Raqami | D4: Jami Borish Reyslari | E4: Jami Qaytish Reyslari | F4: Jami Umumiy Reyslar | G4: Avtomat Sanalgan Pustoylar (-) | H4: 1 ta Reys Stavkasi | I4: Jami Hisoblangan Oylik | J4: Jami Berilgan Yo'l Puli | K4: Jami Qaytgan Ortiqcha Pul | L4: Mijozdan Kelgan Naqd Pul | M4: Kassa Sof Tushumi
A5: 1 | B5: Baltayev Egambergan | C5: 90 070 HBA | D5: =COUNTA('30 KUNLIK MOLIYA VA REYSLAR'!D5:AG5) | E5: =COUNTA('30 KUNLIK MOLIYA VA REYSLAR'!D6:AG6) | F5: =D5+E5 | G5: =COUNTIF('30 KUNLIK MOLIYA VA REYSLAR'!D5:AG5, "*pustoy*") + COUNTIF('30 KUNLIK MOLIYA VA REYSLAR'!D6:AG6, "*pustoy*") | I5: =(F5-G5)*H5 | J5: =SUM('30 KUNLIK MOLIYA VA REYSLAR'!D7:AG7) | K5: =SUM('30 KUNLIK MOLIYA VA REYSLAR'!D8:AG8) | L5: =SUM('30 KUNLIK MOLIYA VA REYSLAR'!D9:AG9) | M5: =(L5+K5)-J5-I5
A6: 2 | B6: Kazakov Yunus | C6: 90 636 HBA | D6: =COUNTA('30 KUNLIK MOLIYA VA REYSLAR'!D11:AG11) | E6: =COUNTA('30 KUNLIK MOLIYA VA REYSLAR'!D12:AG12) | F6: =D6+E6 | G6: =COUNTIF('30 KUNLIK MOLIYA VA REYSLAR'!D11:AG11, "*pustoy*") + COUNTIF('30 KUNLIK MOLIYA VA REYSLAR'!D12:AG12, "*pustoy*") | I6: =(F6-G6)*H6 | J6: =SUM('30 KUNLIK MOLIYA VA REYSLAR'!D13:AG13) | K6: =SUM('30 KUNLIK MOLIYA VA REYSLAR'!D14:AG14) | L6: =SUM('30 KUNLIK MOLIYA VA REYSLAR'!D15:AG15) | M6: =(L6+K6)-J6-I6
A7: 3 | B7: ASHIROV FARID | C7: 90 974 GBA | D7: =COUNTA('30 KUNLIK MOLIYA VA REYSLAR'!D17:AG17) | E7: =COUNTA('30 KUNLIK MOLIYA VA REYSLAR'!D18:AG18) | F7: =D7+E7 | G7: =COUNTIF('30 KUNLIK MOLIYA VA REYSLAR'!D17:AG17, "*pustoy*") + COUNTIF('30 KUNLIK MOLIYA VA REYSLAR'!D18:AG18, "*pustoy*") | I7: =(F7-G7)*H7 | J7: =SUM('30 KUNLIK MOLIYA VA REYSLAR'!D19:AG19) | K7: =SUM('30 KUNLIK MOLIYA VA REYSLAR'!D20:AG20) | L7: =SUM('30 KUNLIK MOLIYA VA REYSLAR'!D21:AG21) | M7: =(L7+K7)-J7-I7
A8: 4 | B8: Baltayev Umirbek | C8: 90 844 CBA | D8: =COUNTA('30 KUNLIK MOLIYA VA REYSLAR'!D23:AG23) | E8: =COUNTA('30 KUNLIK MOLIYA VA REYSLAR'!D24:AG24) | F8: =D8+E8 | G8: =COUNTIF('30 KUNLIK MOLIYA VA REYSLAR'!D23:AG23, "*pustoy*") + COUNTIF('30 KUNLIK MOLIYA VA REYSLAR'!D24:AG24, "*pustoy*") | I8: =(F8-G8)*H8 | J8: =SUM('30 KUNLIK MOLIYA VA REYSLAR'!D25:AG25) | K8: =SUM('30 KUNLIK MOLIYA VA REYSLAR'!D26:AG26) | L8: =SUM('30 KUNLIK MOLIYA VA REYSLAR'!D27:AG27) | M8: =(L8+K8)-J8-I8
A9: 5 | B9: Ruzmetov Umidbek | C9: 90 972 GBA | D9: =COUNTA('30 KUNLIK MOLIYA VA REYSLAR'!D29:AG29) | E9: =COUNTA('30 KUNLIK MOLIYA VA REYSLAR'!D30:AG30) | F9: =D9+E9 | G9: =COUNTIF('30 KUNLIK MOLIYA VA REYSLAR'!D29:AG29, "*pustoy*") + COUNTIF('30 KUNLIK MOLIYA VA REYSLAR'!D30:AG30, "*pustoy*") | I9: =(F9-G9)*H9 | J9: =SUM('30 KUNLIK MOLIYA VA REYSLAR'!D31:AG31) | K9: =SUM('30 KUNLIK MOLIYA VA REYSLAR'!D32:AG32) | L9: =SUM('30 KUNLIK MOLIYA VA REYSLAR'!D33:AG33) | M9: =(L9+K9)-J9-I9
A10: 6 | B10: BEGISHEV SARDARBEK | C10: 90 209 JBA | D10: =COUNTA('30 KUNLIK MOLIYA VA REYSLAR'!D35:AG35) | E10: =COUNTA('30 KUNLIK MOLIYA VA REYSLAR'!D36:AG36) | F10: =D10+E10 | G10: =COUNTIF('30 KUNLIK MOLIYA VA REYSLAR'!D35:AG35, "*pustoy*") + COUNTIF('30 KUNLIK MOLIYA VA REYSLAR'!D36:AG36, "*pustoy*") | I10: =(F10-G10)*H10 | J10: =SUM('30 KUNLIK MOLIYA VA REYSLAR'!D37:AG37) | K10: =SUM('30 KUNLIK MOLIYA VA REYSLAR'!D38:AG38) | L10: =SUM('30 KUNLIK MOLIYA VA REYSLAR'!D39:AG39) | M10: =(L10+K10)-J10-I10
A11: 7 | B11: BALTAYEV DILSHOD | C11: 90 363 HBA | D11: =COUNTA('30 KUNLIK MOLIYA VA REYSLAR'!D41:AG41) | E11: =COUNTA('30 KUNLIK MOLIYA VA REYSLAR'!D42:AG42) | F11: =D11+E11 | G11: =COUNTIF('30 KUNLIK MOLIYA VA REYSLAR'!D41:AG41, "*pustoy*") + COUNTIF('30 KUNLIK MOLIYA VA REYSLAR'!D42:AG42, "*pustoy*") | I11: =(F11-G11)*H11 | J11: =SUM('30 KUNLIK MOLIYA VA REYSLAR'!D43:AG43) | K11: =SUM('30 KUNLIK MOLIYA VA REYSLAR'!D44:AG44) | L11: =SUM('30 KUNLIK MOLIYA VA REYSLAR'!D45:AG45) | M11: =(L11+K11)-J11-I11
A12: 8 | B12: Adambayev Umirbek | C12: 90 303 ZAA | D12: =COUNTA('30 KUNLIK MOLIYA VA REYSLAR'!D47:AG47) | E12: =COUNTA('30 KUNLIK MOLIYA VA REYSLAR'!D48:AG48) | F12: =D12+E12 | G12: =COUNTIF('30 KUNLIK MOLIYA VA REYSLAR'!D47:AG47, "*pustoy*") + COUNTIF('30 KUNLIK MOLIYA VA REYSLAR'!D48:AG48, "*pustoy*") | I12: =(F12-G12)*H12 | J12: =SUM('30 KUNLIK MOLIYA VA REYSLAR'!D49:AG49) | K12: =SUM('30 KUNLIK MOLIYA VA REYSLAR'!D50:AG50) | L12: =SUM('30 KUNLIK MOLIYA VA REYSLAR'!D51:AG51) | M12: =(L12+K12)-J12-I12
A13: 9 | B13: Isoilov Muhammad | C13: 90 973 GBA | D13: =COUNTA('30 KUNLIK MOLIYA VA REYSLAR'!D53:AG53) | E13: =COUNTA('30 KUNLIK MOLIYA VA REYSLAR'!D54:AG54) | F13: =D13+E13 | G13: =COUNTIF('30 KUNLIK MOLIYA VA REYSLAR'!D53:AG53, "*pustoy*") + COUNTIF('30 KUNLIK MOLIYA VA REYSLAR'!D54:AG54, "*pustoy*") | I13: =(F13-G13)*H13 | J13: =SUM('30 KUNLIK MOLIYA VA REYSLAR'!D55:AG55) | K13: =SUM('30 KUNLIK MOLIYA VA REYSLAR'!D56:AG56) | L13: =SUM('30 KUNLIK MOLIYA VA REYSLAR'!D57:AG57) | M13: =(L13+K13)-J13-I13

Sheet 30 KUNLIK MOLIYA VA REYSLAR
A1: KUNLIK JONLI JADVAL (IYUN OYI - 2026)
A2: Borish yoki Qaytish qatoriga 'pustoy' deb yozib ketsangiz kifoya.
A4: Haydovchi F.I.O | B4: Davlat Raqami | C4: Amaliyot Turi | D4: 01.06.2026 | E4: 02.06.2026 | F4: 03.06.2026 | G4: 04.06.2026 | H4: 05.06.2026 | I4: 06.06.2026 | J4: 07.06.2026 | K4: 08.06.2026 | L4: 09.06.2026 | M4: 10.06.2026 | N4: 11.06.2026 | O4: 12.06.2026 | P4: 13.06.2026 | Q4: 14.06.2026 | R4: 15.06.2026 | S4: 16.06.2026 | T4: 17.06.2026 | U4: 18.06.2026 | V4: 19.06.2026 | W4: 20.06.2026 | X4: 21.06.2026 | Y4: 22.06.2026 | Z4: 23.06.2026 | AA4: 24.06.2026 | AB4: 25.06.2026 | AC4: 26.06.2026 | AD4: 27.06.2026 | AE4: 28.06.2026 | AF4: 29.06.2026 | AG4: 30.06.2026
A5: Baltayev Egambergan | B5: 90 070 HBA | C5: BORISH (Yo'nalish)
C6: QAYTISH (Yo'nalish)
C7: Yo'l xarajati berildi (-)
C8: Haydovchidan qaytgan pul (+)
C9: Mijozdan naqd kelgan pul (+)
C10: Haydovchi oyligi (Reys uchun) (-)
A11: Kazakov Yunus | B11: 90 636 HBA | C11: BORISH (Yo'nalish)
C12: QAYTISH (Yo'nalish)
C13: Yo'l xarajati berildi (-)
C14: Haydovchidan qaytgan pul (+)
C15: Mijozdan naqd kelgan pul (+)
C16: Haydovchi oyligi (Reys uchun) (-)
A17: ASHIROV FARID | B17: 90 974 GBA | C17: BORISH (Yo'nalish)
C18: QAYTISH (Yo'nalish)
C19: Yo'l xarajati berildi (-)
C20: Haydovchidan qaytgan pul (+)
C21: Mijozdan naqd kelgan pul (+)
C22: Haydovchi oyligi (Reys uchun) (-)
A23: Baltayev Umirbek | B23: 90 844 CBA | C23: BORISH (Yo'nalish)
C24: QAYTISH (Yo'nalish)
C25: Yo'l xarajati berildi (-)
C26: Haydovchidan qaytgan pul (+)
C27: Mijozdan naqd kelgan pul (+)
C28: Haydovchi oyligi (Reys uchun) (-)
A29: Ruzmetov Umidbek | B29: 90 972 GBA | C29: BORISH (Yo'nalish)
C30: QAYTISH (Yo'nalish)
C31: Yo'l xarajati berildi (-)
C32: Haydovchidan qaytgan pul (+)
C33: Mijozdan naqd kelgan pul (+)
C34: Haydovchi oyligi (Reys uchun) (-)
A35: BEGISHEV SARDARBEK | B35: 90 209 JBA | C35: BORISH (Yo'nalish)
C36: QAYTISH (Yo'nalish)
C37: Yo'l xarajati berildi (-)
C38: Haydovchidan qaytgan pul (+)
C39: Mijozdan naqd kelgan pul (+)
C40: Haydovchi oyligi (Reys uchun) (-)
A41: BALTAYEV DILSHOD | B41: 90 363 HBA | C41: BORISH (Yo'nalish)
...
